
Traceback (most recent call last):
  File "/var/www/vhosts/edefrutos2025.xyz/httpdocs/.venv/lib/python3.8/site-packages/gunicorn/arbiter.py", line 608, in spawn_worker
    worker.init_process()
  File "/var/www/vhosts/edefrutos2025.xyz/httpdocs/.venv/lib/python3.8/site-packages/gunicorn/workers/gthread.py", line 94, in init_process
    super().init_process()
  File "/var/www/vhosts/edefrutos2025.xyz/httpdocs/.venv/lib/python3.8/site-packages/gunicorn/workers/base.py", line 143, in init_process
    self.run()
  File "/var/www/vhosts/edefrutos2025.xyz/httpdocs/.venv/lib/python3.8/site-packages/gunicorn/workers/gthread.py", line 213, in run
    callback(key.fileobj)
  File "/var/www/vhosts/edefrutos2025.xyz/httpdocs/.venv/lib/python3.8/site-packages/gunicorn/workers/gthread.py", line 149, in on_client_socket_readable
    self.enqueue_req(conn)
  File "/var/www/vhosts/edefrutos2025.xyz/httpdocs/.venv/lib/python3.8/site-packages/gunicorn/workers/gthread.py", line 116, in enqueue_req
    fs = self.tpool.submit(self.handle, conn)
  File "/usr/lib/python3.8/concurrent/futures/thread.py", line 188, in submit
    self._adjust_thread_count()
  File "/usr/lib/python3.8/concurrent/futures/thread.py", line 213, in _adjust_thread_count
    t.start()
  File "/usr/lib/python3.8/threading.py", line 852, in start
    _start_new_thread(self._bootstrap, ())
RuntimeError: can't start new thread
Traceback (most recent call last):
  File "/var/www/vhosts/edefrutos2025.xyz/httpdocs/.venv/lib/python3.8/site-packages/gunicorn/arbiter.py", line 608, in spawn_worker
    worker.init_process()
  File "/var/www/vhosts/edefrutos2025.xyz/httpdocs/.venv/lib/python3.8/site-packages/gunicorn/workers/gthread.py", line 94, in init_process
    super().init_process()
  File "/var/www/vhosts/edefrutos2025.xyz/httpdocs/.venv/lib/python3.8/site-packages/gunicorn/workers/base.py", line 143, in init_process
    self.run()
  File "/var/www/vhosts/edefrutos2025.xyz/httpdocs/.venv/lib/python3.8/site-packages/gunicorn/workers/gthread.py", line 213, in run
    callback(key.fileobj)
  File "/var/www/vhosts/edefrutos2025.xyz/httpdocs/.venv/lib/python3.8/site-packages/gunicorn/workers/gthread.py", line 149, in on_client_socket_readable
    self.enqueue_req(conn)
  File "/var/www/vhosts/edefrutos2025.xyz/httpdocs/.venv/lib/python3.8/site-packages/gunicorn/workers/gthread.py", line 116, in enqueue_req
    fs = self.tpool.submit(self.handle, conn)
  File "/usr/lib/python3.8/concurrent/futures/thread.py", line 188, in submit
    self._adjust_thread_count()
  File "/usr/lib/python3.8/concurrent/futures/thread.py", line 213, in _adjust_thread_count
    t.start()
  File "/usr/lib/python3.8/threading.py", line 852, in start
    _start_new_thread(self._bootstrap, ())
RuntimeError: can't start new thread
Traceback (most recent call last):
  File "/var/www/vhosts/edefrutos2025.xyz/httpdocs/.venv/lib/python3.8/site-packages/gunicorn/arbiter.py", line 208, in run
    self.sleep()
  File "/var/www/vhosts/edefrutos2025.xyz/httpdocs/.venv/lib/python3.8/site-packages/gunicorn/arbiter.py", line 359, in sleep
    ready = select.select([self.PIPE[0]], [], [], 1.0)
  File "/var/www/vhosts/edefrutos2025.xyz/httpdocs/.venv/lib/python3.8/site-packages/gunicorn/arbiter.py", line 241, in handle_chld
    self.reap_workers()
  File "/var/www/vhosts/edefrutos2025.xyz/httpdocs/.venv/lib/python3.8/site-packages/gunicorn/arbiter.py", line 559, in reap_workers
    self.cfg.child_exit(self, worker)
  File "/var/www/vhosts/edefrutos2025.xyz/httpdocs/gunicorn_config.py", line 106, in child_exit
    server.log.warning(f"Worker {worker.pid} ha terminado con código de salida {worker.exitcode}")
AttributeError: 'ThreadWorker' object has no attribute 'exitcode'
Traceback (most recent call last):
  File "/var/www/vhosts/edefrutos2025.xyz/httpdocs/.venv/lib/python3.8/site-packages/gunicorn/arbiter.py", line 608, in spawn_worker
    worker.init_process()
  File "/var/www/vhosts/edefrutos2025.xyz/httpdocs/.venv/lib/python3.8/site-packages/gunicorn/workers/gthread.py", line 94, in init_process
    super().init_process()
  File "/var/www/vhosts/edefrutos2025.xyz/httpdocs/.venv/lib/python3.8/site-packages/gunicorn/workers/base.py", line 143, in init_process
    self.run()
  File "/var/www/vhosts/edefrutos2025.xyz/httpdocs/.venv/lib/python3.8/site-packages/gunicorn/workers/gthread.py", line 213, in run
    callback(key.fileobj)
  File "/var/www/vhosts/edefrutos2025.xyz/httpdocs/.venv/lib/python3.8/site-packages/gunicorn/workers/gthread.py", line 149, in on_client_socket_readable
    self.enqueue_req(conn)
  File "/var/www/vhosts/edefrutos2025.xyz/httpdocs/.venv/lib/python3.8/site-packages/gunicorn/workers/gthread.py", line 116, in enqueue_req
    fs = self.tpool.submit(self.handle, conn)
  File "/usr/lib/python3.8/concurrent/futures/thread.py", line 188, in submit
    self._adjust_thread_count()
  File "/usr/lib/python3.8/concurrent/futures/thread.py", line 213, in _adjust_thread_count
    t.start()
  File "/usr/lib/python3.8/threading.py", line 852, in start
    _start_new_thread(self._bootstrap, ())
RuntimeError: can't start new thread
Traceback (most recent call last):
  File "/var/www/vhosts/edefrutos2025.xyz/httpdocs/.venv/lib/python3.8/site-packages/gunicorn/arbiter.py", line 608, in spawn_worker
    worker.init_process()
  File "/var/www/vhosts/edefrutos2025.xyz/httpdocs/.venv/lib/python3.8/site-packages/gunicorn/workers/gthread.py", line 94, in init_process
    super().init_process()
  File "/var/www/vhosts/edefrutos2025.xyz/httpdocs/.venv/lib/python3.8/site-packages/gunicorn/workers/base.py", line 143, in init_process
    self.run()
  File "/var/www/vhosts/edefrutos2025.xyz/httpdocs/.venv/lib/python3.8/site-packages/gunicorn/workers/gthread.py", line 213, in run
    callback(key.fileobj)
  File "/var/www/vhosts/edefrutos2025.xyz/httpdocs/.venv/lib/python3.8/site-packages/gunicorn/workers/gthread.py", line 149, in on_client_socket_readable
    self.enqueue_req(conn)
  File "/var/www/vhosts/edefrutos2025.xyz/httpdocs/.venv/lib/python3.8/site-packages/gunicorn/workers/gthread.py", line 116, in enqueue_req
    fs = self.tpool.submit(self.handle, conn)
  File "/usr/lib/python3.8/concurrent/futures/thread.py", line 188, in submit
    self._adjust_thread_count()
  File "/usr/lib/python3.8/concurrent/futures/thread.py", line 213, in _adjust_thread_count
    t.start()
  File "/usr/lib/python3.8/threading.py", line 852, in start
    _start_new_thread(self._bootstrap, ())
RuntimeError: can't start new thread
Traceback (most recent call last):
  File "/var/www/vhosts/edefrutos2025.xyz/httpdocs/.venv/lib/python3.8/site-packages/gunicorn/arbiter.py", line 208, in run
    self.sleep()
  File "/var/www/vhosts/edefrutos2025.xyz/httpdocs/.venv/lib/python3.8/site-packages/gunicorn/arbiter.py", line 359, in sleep
    ready = select.select([self.PIPE[0]], [], [], 1.0)
  File "/var/www/vhosts/edefrutos2025.xyz/httpdocs/.venv/lib/python3.8/site-packages/gunicorn/arbiter.py", line 241, in handle_chld
    self.reap_workers()
  File "/var/www/vhosts/edefrutos2025.xyz/httpdocs/.venv/lib/python3.8/site-packages/gunicorn/arbiter.py", line 559, in reap_workers
    self.cfg.child_exit(self, worker)
  File "/var/www/vhosts/edefrutos2025.xyz/httpdocs/gunicorn_config.py", line 106, in child_exit
    server.log.warning(f"Worker {worker.pid} ha terminado con código de salida {worker.exitcode}")
AttributeError: 'ThreadWorker' object has no attribute 'exitcode'
Traceback (most recent call last):
  File "/var/www/vhosts/edefrutos2025.xyz/httpdocs/.venv/lib/python3.8/site-packages/gunicorn/arbiter.py", line 608, in spawn_worker
    worker.init_process()
  File "/var/www/vhosts/edefrutos2025.xyz/httpdocs/.venv/lib/python3.8/site-packages/gunicorn/workers/gthread.py", line 94, in init_process
    super().init_process()
  File "/var/www/vhosts/edefrutos2025.xyz/httpdocs/.venv/lib/python3.8/site-packages/gunicorn/workers/base.py", line 143, in init_process
    self.run()
  File "/var/www/vhosts/edefrutos2025.xyz/httpdocs/.venv/lib/python3.8/site-packages/gunicorn/workers/gthread.py", line 213, in run
    callback(key.fileobj)
  File "/var/www/vhosts/edefrutos2025.xyz/httpdocs/.venv/lib/python3.8/site-packages/gunicorn/workers/gthread.py", line 149, in on_client_socket_readable
    self.enqueue_req(conn)
  File "/var/www/vhosts/edefrutos2025.xyz/httpdocs/.venv/lib/python3.8/site-packages/gunicorn/workers/gthread.py", line 116, in enqueue_req
    fs = self.tpool.submit(self.handle, conn)
  File "/usr/lib/python3.8/concurrent/futures/thread.py", line 188, in submit
    self._adjust_thread_count()
  File "/usr/lib/python3.8/concurrent/futures/thread.py", line 213, in _adjust_thread_count
    t.start()
  File "/usr/lib/python3.8/threading.py", line 852, in start
    _start_new_thread(self._bootstrap, ())
RuntimeError: can't start new thread
Traceback (most recent call last):
  File "/var/www/vhosts/edefrutos2025.xyz/httpdocs/.venv/lib/python3.8/site-packages/gunicorn/arbiter.py", line 608, in spawn_worker
    worker.init_process()
  File "/var/www/vhosts/edefrutos2025.xyz/httpdocs/.venv/lib/python3.8/site-packages/gunicorn/workers/gthread.py", line 94, in init_process
    super().init_process()
  File "/var/www/vhosts/edefrutos2025.xyz/httpdocs/.venv/lib/python3.8/site-packages/gunicorn/workers/base.py", line 143, in init_process
    self.run()
  File "/var/www/vhosts/edefrutos2025.xyz/httpdocs/.venv/lib/python3.8/site-packages/gunicorn/workers/gthread.py", line 213, in run
    callback(key.fileobj)
  File "/var/www/vhosts/edefrutos2025.xyz/httpdocs/.venv/lib/python3.8/site-packages/gunicorn/workers/gthread.py", line 149, in on_client_socket_readable
    self.enqueue_req(conn)
  File "/var/www/vhosts/edefrutos2025.xyz/httpdocs/.venv/lib/python3.8/site-packages/gunicorn/workers/gthread.py", line 116, in enqueue_req
    fs = self.tpool.submit(self.handle, conn)
  File "/usr/lib/python3.8/concurrent/futures/thread.py", line 188, in submit
    self._adjust_thread_count()
  File "/usr/lib/python3.8/concurrent/futures/thread.py", line 213, in _adjust_thread_count
    t.start()
  File "/usr/lib/python3.8/threading.py", line 852, in start
    _start_new_thread(self._bootstrap, ())
RuntimeError: can't start new thread
Traceback (most recent call last):
  File "/var/www/vhosts/edefrutos2025.xyz/httpdocs/.venv/lib/python3.8/site-packages/gunicorn/arbiter.py", line 208, in run
    self.sleep()
  File "/var/www/vhosts/edefrutos2025.xyz/httpdocs/.venv/lib/python3.8/site-packages/gunicorn/arbiter.py", line 359, in sleep
    ready = select.select([self.PIPE[0]], [], [], 1.0)
  File "/var/www/vhosts/edefrutos2025.xyz/httpdocs/.venv/lib/python3.8/site-packages/gunicorn/arbiter.py", line 241, in handle_chld
    self.reap_workers()
  File "/var/www/vhosts/edefrutos2025.xyz/httpdocs/.venv/lib/python3.8/site-packages/gunicorn/arbiter.py", line 559, in reap_workers
    self.cfg.child_exit(self, worker)
  File "/var/www/vhosts/edefrutos2025.xyz/httpdocs/gunicorn_config.py", line 106, in child_exit
    server.log.warning(f"Worker {worker.pid} ha terminado con código de salida {worker.exitcode}")
AttributeError: 'ThreadWorker' object has no attribute 'exitcode'
Traceback (most recent call last):
  File "/var/www/vhosts/edefrutos2025.xyz/httpdocs/.venv/lib/python3.8/site-packages/gunicorn/arbiter.py", line 608, in spawn_worker
    worker.init_process()
  File "/var/www/vhosts/edefrutos2025.xyz/httpdocs/.venv/lib/python3.8/site-packages/gunicorn/workers/gthread.py", line 94, in init_process
    super().init_process()
  File "/var/www/vhosts/edefrutos2025.xyz/httpdocs/.venv/lib/python3.8/site-packages/gunicorn/workers/base.py", line 143, in init_process
    self.run()
  File "/var/www/vhosts/edefrutos2025.xyz/httpdocs/.venv/lib/python3.8/site-packages/gunicorn/workers/gthread.py", line 213, in run
    callback(key.fileobj)
  File "/var/www/vhosts/edefrutos2025.xyz/httpdocs/.venv/lib/python3.8/site-packages/gunicorn/workers/gthread.py", line 149, in on_client_socket_readable
    self.enqueue_req(conn)
  File "/var/www/vhosts/edefrutos2025.xyz/httpdocs/.venv/lib/python3.8/site-packages/gunicorn/workers/gthread.py", line 116, in enqueue_req
    fs = self.tpool.submit(self.handle, conn)
  File "/usr/lib/python3.8/concurrent/futures/thread.py", line 188, in submit
    self._adjust_thread_count()
  File "/usr/lib/python3.8/concurrent/futures/thread.py", line 213, in _adjust_thread_count
    t.start()
  File "/usr/lib/python3.8/threading.py", line 852, in start
    _start_new_thread(self._bootstrap, ())
RuntimeError: can't start new thread
Traceback (most recent call last):
  File "/var/www/vhosts/edefrutos2025.xyz/httpdocs/.venv/lib/python3.8/site-packages/gunicorn/arbiter.py", line 608, in spawn_worker
    worker.init_process()
  File "/var/www/vhosts/edefrutos2025.xyz/httpdocs/.venv/lib/python3.8/site-packages/gunicorn/workers/gthread.py", line 94, in init_process
    super().init_process()
  File "/var/www/vhosts/edefrutos2025.xyz/httpdocs/.venv/lib/python3.8/site-packages/gunicorn/workers/base.py", line 143, in init_process
    self.run()
  File "/var/www/vhosts/edefrutos2025.xyz/httpdocs/.venv/lib/python3.8/site-packages/gunicorn/workers/gthread.py", line 213, in run
    callback(key.fileobj)
  File "/var/www/vhosts/edefrutos2025.xyz/httpdocs/.venv/lib/python3.8/site-packages/gunicorn/workers/gthread.py", line 149, in on_client_socket_readable
    self.enqueue_req(conn)
  File "/var/www/vhosts/edefrutos2025.xyz/httpdocs/.venv/lib/python3.8/site-packages/gunicorn/workers/gthread.py", line 116, in enqueue_req
    fs = self.tpool.submit(self.handle, conn)
  File "/usr/lib/python3.8/concurrent/futures/thread.py", line 188, in submit
    self._adjust_thread_count()
  File "/usr/lib/python3.8/concurrent/futures/thread.py", line 213, in _adjust_thread_count
    t.start()
  File "/usr/lib/python3.8/threading.py", line 852, in start
    _start_new_thread(self._bootstrap, ())
RuntimeError: can't start new thread
Traceback (most recent call last):
  File "/var/www/vhosts/edefrutos2025.xyz/httpdocs/.venv/lib/python3.8/site-packages/gunicorn/arbiter.py", line 608, in spawn_worker
    worker.init_process()
  File "/var/www/vhosts/edefrutos2025.xyz/httpdocs/.venv/lib/python3.8/site-packages/gunicorn/workers/gthread.py", line 94, in init_process
    super().init_process()
  File "/var/www/vhosts/edefrutos2025.xyz/httpdocs/.venv/lib/python3.8/site-packages/gunicorn/workers/base.py", line 143, in init_process
    self.run()
  File "/var/www/vhosts/edefrutos2025.xyz/httpdocs/.venv/lib/python3.8/site-packages/gunicorn/workers/gthread.py", line 213, in run
    callback(key.fileobj)
  File "/var/www/vhosts/edefrutos2025.xyz/httpdocs/.venv/lib/python3.8/site-packages/gunicorn/workers/gthread.py", line 149, in on_client_socket_readable
    self.enqueue_req(conn)
  File "/var/www/vhosts/edefrutos2025.xyz/httpdocs/.venv/lib/python3.8/site-packages/gunicorn/workers/gthread.py", line 116, in enqueue_req
    fs = self.tpool.submit(self.handle, conn)
  File "/usr/lib/python3.8/concurrent/futures/thread.py", line 188, in submit
    self._adjust_thread_count()
  File "/usr/lib/python3.8/concurrent/futures/thread.py", line 213, in _adjust_thread_count
    t.start()
  File "/usr/lib/python3.8/threading.py", line 852, in start
    _start_new_thread(self._bootstrap, ())
RuntimeError: can't start new thread
Traceback (most recent call last):
  File "/var/www/vhosts/edefrutos2025.xyz/httpdocs/.venv/lib/python3.8/site-packages/gunicorn/arbiter.py", line 208, in run
    self.sleep()
  File "/var/www/vhosts/edefrutos2025.xyz/httpdocs/.venv/lib/python3.8/site-packages/gunicorn/arbiter.py", line 359, in sleep
    ready = select.select([self.PIPE[0]], [], [], 1.0)
  File "/var/www/vhosts/edefrutos2025.xyz/httpdocs/.venv/lib/python3.8/site-packages/gunicorn/arbiter.py", line 241, in handle_chld
    self.reap_workers()
  File "/var/www/vhosts/edefrutos2025.xyz/httpdocs/.venv/lib/python3.8/site-packages/gunicorn/arbiter.py", line 559, in reap_workers
    self.cfg.child_exit(self, worker)
  File "/var/www/vhosts/edefrutos2025.xyz/httpdocs/gunicorn_config.py", line 106, in child_exit
    server.log.warning(f"Worker {worker.pid} ha terminado con código de salida {worker.exitcode}")
AttributeError: 'ThreadWorker' object has no attribute 'exitcode'
Traceback (most recent call last):
  File "/var/www/vhosts/edefrutos2025.xyz/httpdocs/.venv/lib/python3.8/site-packages/gunicorn/arbiter.py", line 608, in spawn_worker
    worker.init_process()
  File "/var/www/vhosts/edefrutos2025.xyz/httpdocs/.venv/lib/python3.8/site-packages/gunicorn/workers/gthread.py", line 94, in init_process
    super().init_process()
  File "/var/www/vhosts/edefrutos2025.xyz/httpdocs/.venv/lib/python3.8/site-packages/gunicorn/workers/base.py", line 143, in init_process
    self.run()
  File "/var/www/vhosts/edefrutos2025.xyz/httpdocs/.venv/lib/python3.8/site-packages/gunicorn/workers/gthread.py", line 213, in run
    callback(key.fileobj)
  File "/var/www/vhosts/edefrutos2025.xyz/httpdocs/.venv/lib/python3.8/site-packages/gunicorn/workers/gthread.py", line 149, in on_client_socket_readable
    self.enqueue_req(conn)
  File "/var/www/vhosts/edefrutos2025.xyz/httpdocs/.venv/lib/python3.8/site-packages/gunicorn/workers/gthread.py", line 116, in enqueue_req
    fs = self.tpool.submit(self.handle, conn)
  File "/usr/lib/python3.8/concurrent/futures/thread.py", line 188, in submit
    self._adjust_thread_count()
  File "/usr/lib/python3.8/concurrent/futures/thread.py", line 213, in _adjust_thread_count
    t.start()
  File "/usr/lib/python3.8/threading.py", line 852, in start
    _start_new_thread(self._bootstrap, ())
RuntimeError: can't start new thread
Traceback (most recent call last):
  File "/var/www/vhosts/edefrutos2025.xyz/httpdocs/.venv/lib/python3.8/site-packages/gunicorn/arbiter.py", line 608, in spawn_worker
    worker.init_process()
  File "/var/www/vhosts/edefrutos2025.xyz/httpdocs/.venv/lib/python3.8/site-packages/gunicorn/workers/gthread.py", line 94, in init_process
    super().init_process()
  File "/var/www/vhosts/edefrutos2025.xyz/httpdocs/.venv/lib/python3.8/site-packages/gunicorn/workers/base.py", line 143, in init_process
    self.run()
  File "/var/www/vhosts/edefrutos2025.xyz/httpdocs/.venv/lib/python3.8/site-packages/gunicorn/workers/gthread.py", line 213, in run
    callback(key.fileobj)
  File "/var/www/vhosts/edefrutos2025.xyz/httpdocs/.venv/lib/python3.8/site-packages/gunicorn/workers/gthread.py", line 149, in on_client_socket_readable
    self.enqueue_req(conn)
  File "/var/www/vhosts/edefrutos2025.xyz/httpdocs/.venv/lib/python3.8/site-packages/gunicorn/workers/gthread.py", line 116, in enqueue_req
    fs = self.tpool.submit(self.handle, conn)
  File "/usr/lib/python3.8/concurrent/futures/thread.py", line 188, in submit
    self._adjust_thread_count()
  File "/usr/lib/python3.8/concurrent/futures/thread.py", line 213, in _adjust_thread_count
    t.start()
  File "/usr/lib/python3.8/threading.py", line 852, in start
    _start_new_thread(self._bootstrap, ())
RuntimeError: can't start new thread
Traceback (most recent call last):
  File "/var/www/vhosts/edefrutos2025.xyz/httpdocs/.venv/lib/python3.8/site-packages/gunicorn/arbiter.py", line 208, in run
    self.sleep()
  File "/var/www/vhosts/edefrutos2025.xyz/httpdocs/.venv/lib/python3.8/site-packages/gunicorn/arbiter.py", line 359, in sleep
    ready = select.select([self.PIPE[0]], [], [], 1.0)
  File "/var/www/vhosts/edefrutos2025.xyz/httpdocs/.venv/lib/python3.8/site-packages/gunicorn/arbiter.py", line 241, in handle_chld
    self.reap_workers()
  File "/var/www/vhosts/edefrutos2025.xyz/httpdocs/.venv/lib/python3.8/site-packages/gunicorn/arbiter.py", line 559, in reap_workers
    self.cfg.child_exit(self, worker)
  File "/var/www/vhosts/edefrutos2025.xyz/httpdocs/gunicorn_config.py", line 106, in child_exit
    server.log.warning(f"Worker {worker.pid} ha terminado con código de salida {worker.exitcode}")
AttributeError: 'ThreadWorker' object has no attribute 'exitcode'
Traceback (most recent call last):
  File "/var/www/vhosts/edefrutos2025.xyz/httpdocs/.venv/lib/python3.8/site-packages/gunicorn/arbiter.py", line 608, in spawn_worker
    worker.init_process()
  File "/var/www/vhosts/edefrutos2025.xyz/httpdocs/.venv/lib/python3.8/site-packages/gunicorn/workers/gthread.py", line 94, in init_process
    super().init_process()
  File "/var/www/vhosts/edefrutos2025.xyz/httpdocs/.venv/lib/python3.8/site-packages/gunicorn/workers/base.py", line 143, in init_process
    self.run()
  File "/var/www/vhosts/edefrutos2025.xyz/httpdocs/.venv/lib/python3.8/site-packages/gunicorn/workers/gthread.py", line 213, in run
    callback(key.fileobj)
  File "/var/www/vhosts/edefrutos2025.xyz/httpdocs/.venv/lib/python3.8/site-packages/gunicorn/workers/gthread.py", line 149, in on_client_socket_readable
    self.enqueue_req(conn)
  File "/var/www/vhosts/edefrutos2025.xyz/httpdocs/.venv/lib/python3.8/site-packages/gunicorn/workers/gthread.py", line 116, in enqueue_req
    fs = self.tpool.submit(self.handle, conn)
  File "/usr/lib/python3.8/concurrent/futures/thread.py", line 188, in submit
    self._adjust_thread_count()
  File "/usr/lib/python3.8/concurrent/futures/thread.py", line 213, in _adjust_thread_count
    t.start()
  File "/usr/lib/python3.8/threading.py", line 852, in start
    _start_new_thread(self._bootstrap, ())
RuntimeError: can't start new thread
Traceback (most recent call last):
  File "/var/www/vhosts/edefrutos2025.xyz/httpdocs/.venv/lib/python3.8/site-packages/gunicorn/arbiter.py", line 608, in spawn_worker
    worker.init_process()
  File "/var/www/vhosts/edefrutos2025.xyz/httpdocs/.venv/lib/python3.8/site-packages/gunicorn/workers/gthread.py", line 94, in init_process
    super().init_process()
  File "/var/www/vhosts/edefrutos2025.xyz/httpdocs/.venv/lib/python3.8/site-packages/gunicorn/workers/base.py", line 143, in init_process
    self.run()
  File "/var/www/vhosts/edefrutos2025.xyz/httpdocs/.venv/lib/python3.8/site-packages/gunicorn/workers/gthread.py", line 213, in run
    callback(key.fileobj)
  File "/var/www/vhosts/edefrutos2025.xyz/httpdocs/.venv/lib/python3.8/site-packages/gunicorn/workers/gthread.py", line 149, in on_client_socket_readable
    self.enqueue_req(conn)
  File "/var/www/vhosts/edefrutos2025.xyz/httpdocs/.venv/lib/python3.8/site-packages/gunicorn/workers/gthread.py", line 116, in enqueue_req
    fs = self.tpool.submit(self.handle, conn)
  File "/usr/lib/python3.8/concurrent/futures/thread.py", line 188, in submit
    self._adjust_thread_count()
  File "/usr/lib/python3.8/concurrent/futures/thread.py", line 213, in _adjust_thread_count
    t.start()
  File "/usr/lib/python3.8/threading.py", line 852, in start
    _start_new_thread(self._bootstrap, ())
RuntimeError: can't start new thread
Traceback (most recent call last):
  File "/var/www/vhosts/edefrutos2025.xyz/httpdocs/.venv/lib/python3.8/site-packages/gunicorn/arbiter.py", line 208, in run
    self.sleep()
  File "/var/www/vhosts/edefrutos2025.xyz/httpdocs/.venv/lib/python3.8/site-packages/gunicorn/arbiter.py", line 359, in sleep
    ready = select.select([self.PIPE[0]], [], [], 1.0)
  File "/var/www/vhosts/edefrutos2025.xyz/httpdocs/.venv/lib/python3.8/site-packages/gunicorn/arbiter.py", line 241, in handle_chld
    self.reap_workers()
  File "/var/www/vhosts/edefrutos2025.xyz/httpdocs/.venv/lib/python3.8/site-packages/gunicorn/arbiter.py", line 559, in reap_workers
    self.cfg.child_exit(self, worker)
  File "/var/www/vhosts/edefrutos2025.xyz/httpdocs/gunicorn_config.py", line 106, in child_exit
    server.log.warning(f"Worker {worker.pid} ha terminado con código de salida {worker.exitcode}")
AttributeError: 'ThreadWorker' object has no attribute 'exitcode'
Traceback (most recent call last):
  File "/var/www/vhosts/edefrutos2025.xyz/httpdocs/.venv/lib/python3.8/site-packages/gunicorn/arbiter.py", line 608, in spawn_worker
    worker.init_process()
  File "/var/www/vhosts/edefrutos2025.xyz/httpdocs/.venv/lib/python3.8/site-packages/gunicorn/workers/gthread.py", line 94, in init_process
    super().init_process()
  File "/var/www/vhosts/edefrutos2025.xyz/httpdocs/.venv/lib/python3.8/site-packages/gunicorn/workers/base.py", line 143, in init_process
    self.run()
  File "/var/www/vhosts/edefrutos2025.xyz/httpdocs/.venv/lib/python3.8/site-packages/gunicorn/workers/gthread.py", line 213, in run
    callback(key.fileobj)
  File "/var/www/vhosts/edefrutos2025.xyz/httpdocs/.venv/lib/python3.8/site-packages/gunicorn/workers/gthread.py", line 149, in on_client_socket_readable
    self.enqueue_req(conn)
  File "/var/www/vhosts/edefrutos2025.xyz/httpdocs/.venv/lib/python3.8/site-packages/gunicorn/workers/gthread.py", line 116, in enqueue_req
    fs = self.tpool.submit(self.handle, conn)
  File "/usr/lib/python3.8/concurrent/futures/thread.py", line 188, in submit
    self._adjust_thread_count()
  File "/usr/lib/python3.8/concurrent/futures/thread.py", line 213, in _adjust_thread_count
    t.start()
  File "/usr/lib/python3.8/threading.py", line 852, in start
    _start_new_thread(self._bootstrap, ())
RuntimeError: can't start new thread
Traceback (most recent call last):
  File "/var/www/vhosts/edefrutos2025.xyz/httpdocs/.venv/lib/python3.8/site-packages/gunicorn/arbiter.py", line 608, in spawn_worker
    worker.init_process()
  File "/var/www/vhosts/edefrutos2025.xyz/httpdocs/.venv/lib/python3.8/site-packages/gunicorn/workers/gthread.py", line 94, in init_process
    super().init_process()
  File "/var/www/vhosts/edefrutos2025.xyz/httpdocs/.venv/lib/python3.8/site-packages/gunicorn/workers/base.py", line 143, in init_process
    self.run()
  File "/var/www/vhosts/edefrutos2025.xyz/httpdocs/.venv/lib/python3.8/site-packages/gunicorn/workers/gthread.py", line 213, in run
    callback(key.fileobj)
  File "/var/www/vhosts/edefrutos2025.xyz/httpdocs/.venv/lib/python3.8/site-packages/gunicorn/workers/gthread.py", line 149, in on_client_socket_readable
    self.enqueue_req(conn)
  File "/var/www/vhosts/edefrutos2025.xyz/httpdocs/.venv/lib/python3.8/site-packages/gunicorn/workers/gthread.py", line 116, in enqueue_req
    fs = self.tpool.submit(self.handle, conn)
  File "/usr/lib/python3.8/concurrent/futures/thread.py", line 188, in submit
    self._adjust_thread_count()
  File "/usr/lib/python3.8/concurrent/futures/thread.py", line 213, in _adjust_thread_count
    t.start()
  File "/usr/lib/python3.8/threading.py", line 852, in start
    _start_new_thread(self._bootstrap, ())
RuntimeError: can't start new thread
Traceback (most recent call last):
  File "/var/www/vhosts/edefrutos2025.xyz/httpdocs/.venv/lib/python3.8/site-packages/gunicorn/arbiter.py", line 208, in run
    self.sleep()
  File "/var/www/vhosts/edefrutos2025.xyz/httpdocs/.venv/lib/python3.8/site-packages/gunicorn/arbiter.py", line 359, in sleep
    ready = select.select([self.PIPE[0]], [], [], 1.0)
  File "/var/www/vhosts/edefrutos2025.xyz/httpdocs/.venv/lib/python3.8/site-packages/gunicorn/arbiter.py", line 241, in handle_chld
    self.reap_workers()
  File "/var/www/vhosts/edefrutos2025.xyz/httpdocs/.venv/lib/python3.8/site-packages/gunicorn/arbiter.py", line 559, in reap_workers
    self.cfg.child_exit(self, worker)
  File "/var/www/vhosts/edefrutos2025.xyz/httpdocs/gunicorn_config.py", line 106, in child_exit
AttributeError: 'ThreadWorker' object has no attribute 'exitcode'
Traceback (most recent call last):
  File "/var/www/vhosts/edefrutos2025.xyz/httpdocs/.venv/lib/python3.8/site-packages/gunicorn/arbiter.py", line 201, in run
    self.manage_workers()
  File "/var/www/vhosts/edefrutos2025.xyz/httpdocs/.venv/lib/python3.8/site-packages/gunicorn/arbiter.py", line 570, in manage_workers
    self.spawn_workers()
  File "/var/www/vhosts/edefrutos2025.xyz/httpdocs/.venv/lib/python3.8/site-packages/gunicorn/arbiter.py", line 641, in spawn_workers
    self.spawn_worker()
  File "/var/www/vhosts/edefrutos2025.xyz/httpdocs/.venv/lib/python3.8/site-packages/gunicorn/arbiter.py", line 592, in spawn_worker
    pid = os.fork()
BlockingIOError: [Errno 11] Resource temporarily unavailable
Traceback (most recent call last):
  File "/var/www/vhosts/edefrutos2025.xyz/httpdocs/.venv/lib/python3.8/site-packages/gunicorn/arbiter.py", line 201, in run
    self.manage_workers()
  File "/var/www/vhosts/edefrutos2025.xyz/httpdocs/.venv/lib/python3.8/site-packages/gunicorn/arbiter.py", line 570, in manage_workers
    self.spawn_workers()
  File "/var/www/vhosts/edefrutos2025.xyz/httpdocs/.venv/lib/python3.8/site-packages/gunicorn/arbiter.py", line 641, in spawn_workers
    self.spawn_worker()
  File "/var/www/vhosts/edefrutos2025.xyz/httpdocs/.venv/lib/python3.8/site-packages/gunicorn/arbiter.py", line 592, in spawn_worker
    pid = os.fork()
BlockingIOError: [Errno 11] Resource temporarily unavailable
Traceback (most recent call last):
  File "/var/www/vhosts/edefrutos2025.xyz/httpdocs/.venv/lib/python3.8/site-packages/gunicorn/arbiter.py", line 201, in run
    self.manage_workers()
  File "/var/www/vhosts/edefrutos2025.xyz/httpdocs/.venv/lib/python3.8/site-packages/gunicorn/arbiter.py", line 570, in manage_workers
    self.spawn_workers()
  File "/var/www/vhosts/edefrutos2025.xyz/httpdocs/.venv/lib/python3.8/site-packages/gunicorn/arbiter.py", line 641, in spawn_workers
    self.spawn_worker()
  File "/var/www/vhosts/edefrutos2025.xyz/httpdocs/.venv/lib/python3.8/site-packages/gunicorn/arbiter.py", line 592, in spawn_worker
    pid = os.fork()
BlockingIOError: [Errno 11] Resource temporarily unavailable
Traceback (most recent call last):
  File "/var/www/vhosts/edefrutos2025.xyz/httpdocs/.venv/lib/python3.8/site-packages/gunicorn/arbiter.py", line 608, in spawn_worker
  File "/var/www/vhosts/edefrutos2025.xyz/httpdocs/.venv/lib/python3.8/site-packages/gunicorn/workers/base.py", line 135, in init_process
  File "/var/www/vhosts/edefrutos2025.xyz/httpdocs/.venv/lib/python3.8/site-packages/gunicorn/workers/base.py", line 147, in load_wsgi
  File "/var/www/vhosts/edefrutos2025.xyz/httpdocs/.venv/lib/python3.8/site-packages/gunicorn/app/base.py", line 66, in wsgi
  File "/var/www/vhosts/edefrutos2025.xyz/httpdocs/.venv/lib/python3.8/site-packages/gunicorn/app/wsgiapp.py", line 57, in load
  File "/var/www/vhosts/edefrutos2025.xyz/httpdocs/.venv/lib/python3.8/site-packages/gunicorn/app/wsgiapp.py", line 47, in load_wsgiapp
  File "/var/www/vhosts/edefrutos2025.xyz/httpdocs/.venv/lib/python3.8/site-packages/gunicorn/util.py", line 370, in import_app
  File "/usr/lib/python3.8/importlib/__init__.py", line 127, in import_module
    return _bootstrap._gcd_import(name[level:], package, level)
  File "<frozen importlib._bootstrap>", line 1014, in _gcd_import
  File "<frozen importlib._bootstrap>", line 991, in _find_and_load
  File "<frozen importlib._bootstrap>", line 973, in _find_and_load_unlocked
ModuleNotFoundError: No module named 'wsgi'
Traceback (most recent call last):
  File "/var/www/vhosts/edefrutos2025.xyz/httpdocs/.venv/lib/python3.8/site-packages/gunicorn/arbiter.py", line 608, in spawn_worker
  File "/var/www/vhosts/edefrutos2025.xyz/httpdocs/.venv/lib/python3.8/site-packages/gunicorn/workers/base.py", line 135, in init_process
  File "/var/www/vhosts/edefrutos2025.xyz/httpdocs/.venv/lib/python3.8/site-packages/gunicorn/workers/base.py", line 147, in load_wsgi
  File "/var/www/vhosts/edefrutos2025.xyz/httpdocs/.venv/lib/python3.8/site-packages/gunicorn/app/base.py", line 66, in wsgi
  File "/var/www/vhosts/edefrutos2025.xyz/httpdocs/.venv/lib/python3.8/site-packages/gunicorn/app/wsgiapp.py", line 57, in load
  File "/var/www/vhosts/edefrutos2025.xyz/httpdocs/.venv/lib/python3.8/site-packages/gunicorn/app/wsgiapp.py", line 47, in load_wsgiapp
  File "/var/www/vhosts/edefrutos2025.xyz/httpdocs/.venv/lib/python3.8/site-packages/gunicorn/util.py", line 370, in import_app
  File "/usr/lib/python3.8/importlib/__init__.py", line 127, in import_module
    return _bootstrap._gcd_import(name[level:], package, level)
  File "<frozen importlib._bootstrap>", line 1014, in _gcd_import
  File "<frozen importlib._bootstrap>", line 991, in _find_and_load
  File "<frozen importlib._bootstrap>", line 973, in _find_and_load_unlocked
ModuleNotFoundError: No module named 'wsgi'
Traceback (most recent call last):
  File "/var/www/vhosts/edefrutos2025.xyz/httpdocs/.venv/lib/python3.8/site-packages/gunicorn/arbiter.py", line 608, in spawn_worker
  File "/var/www/vhosts/edefrutos2025.xyz/httpdocs/.venv/lib/python3.8/site-packages/gunicorn/workers/base.py", line 135, in init_process
  File "/var/www/vhosts/edefrutos2025.xyz/httpdocs/.venv/lib/python3.8/site-packages/gunicorn/workers/base.py", line 147, in load_wsgi
  File "/var/www/vhosts/edefrutos2025.xyz/httpdocs/.venv/lib/python3.8/site-packages/gunicorn/app/base.py", line 66, in wsgi
  File "/var/www/vhosts/edefrutos2025.xyz/httpdocs/.venv/lib/python3.8/site-packages/gunicorn/app/wsgiapp.py", line 57, in load
  File "/var/www/vhosts/edefrutos2025.xyz/httpdocs/.venv/lib/python3.8/site-packages/gunicorn/app/wsgiapp.py", line 47, in load_wsgiapp
  File "/var/www/vhosts/edefrutos2025.xyz/httpdocs/.venv/lib/python3.8/site-packages/gunicorn/util.py", line 370, in import_app
  File "/usr/lib/python3.8/importlib/__init__.py", line 127, in import_module
    return _bootstrap._gcd_import(name[level:], package, level)
  File "<frozen importlib._bootstrap>", line 1014, in _gcd_import
  File "<frozen importlib._bootstrap>", line 991, in _find_and_load
  File "<frozen importlib._bootstrap>", line 973, in _find_and_load_unlocked
ModuleNotFoundError: No module named 'wsgi'
Traceback (most recent call last):
  File "/var/www/vhosts/edefrutos2025.xyz/httpdocs/.venv/lib/python3.8/site-packages/gunicorn/arbiter.py", line 201, in run
    self.manage_workers()
  File "/var/www/vhosts/edefrutos2025.xyz/httpdocs/.venv/lib/python3.8/site-packages/gunicorn/arbiter.py", line 570, in manage_workers
    self.spawn_workers()
  File "/var/www/vhosts/edefrutos2025.xyz/httpdocs/.venv/lib/python3.8/site-packages/gunicorn/arbiter.py", line 641, in spawn_workers
    self.spawn_worker()
  File "/var/www/vhosts/edefrutos2025.xyz/httpdocs/.venv/lib/python3.8/site-packages/gunicorn/arbiter.py", line 592, in spawn_worker
    pid = os.fork()
BlockingIOError: [Errno 11] Resource temporarily unavailable
Traceback (most recent call last):
  File "/var/www/vhosts/edefrutos2025.xyz/httpdocs/.venv/lib/python3.8/site-packages/gunicorn/arbiter.py", line 201, in run
    self.manage_workers()
  File "/var/www/vhosts/edefrutos2025.xyz/httpdocs/.venv/lib/python3.8/site-packages/gunicorn/arbiter.py", line 570, in manage_workers
    self.spawn_workers()
  File "/var/www/vhosts/edefrutos2025.xyz/httpdocs/.venv/lib/python3.8/site-packages/gunicorn/arbiter.py", line 641, in spawn_workers
    self.spawn_worker()
  File "/var/www/vhosts/edefrutos2025.xyz/httpdocs/.venv/lib/python3.8/site-packages/gunicorn/arbiter.py", line 592, in spawn_worker
    pid = os.fork()
BlockingIOError: [Errno 11] Resource temporarily unavailable
Traceback (most recent call last):
  File "/var/www/vhosts/edefrutos2025.xyz/httpdocs/.venv/lib/python3.8/site-packages/gunicorn/arbiter.py", line 201, in run
    self.manage_workers()
  File "/var/www/vhosts/edefrutos2025.xyz/httpdocs/.venv/lib/python3.8/site-packages/gunicorn/arbiter.py", line 570, in manage_workers
    self.spawn_workers()
  File "/var/www/vhosts/edefrutos2025.xyz/httpdocs/.venv/lib/python3.8/site-packages/gunicorn/arbiter.py", line 641, in spawn_workers
    self.spawn_worker()
  File "/var/www/vhosts/edefrutos2025.xyz/httpdocs/.venv/lib/python3.8/site-packages/gunicorn/arbiter.py", line 592, in spawn_worker
    pid = os.fork()
BlockingIOError: [Errno 11] Resource temporarily unavailable
Traceback (most recent call last):
  File "/var/www/vhosts/edefrutos2025.xyz/httpdocs/.venv/lib/python3.8/site-packages/gunicorn/arbiter.py", line 201, in run
    self.manage_workers()
  File "/var/www/vhosts/edefrutos2025.xyz/httpdocs/.venv/lib/python3.8/site-packages/gunicorn/arbiter.py", line 570, in manage_workers
    self.spawn_workers()
  File "/var/www/vhosts/edefrutos2025.xyz/httpdocs/.venv/lib/python3.8/site-packages/gunicorn/arbiter.py", line 641, in spawn_workers
    self.spawn_worker()
  File "/var/www/vhosts/edefrutos2025.xyz/httpdocs/.venv/lib/python3.8/site-packages/gunicorn/arbiter.py", line 592, in spawn_worker
    pid = os.fork()
BlockingIOError: [Errno 11] Resource temporarily unavailable
Traceback (most recent call last):
  File "/var/www/vhosts/edefrutos2025.xyz/httpdocs/.venv/lib/python3.8/site-packages/gunicorn/arbiter.py", line 201, in run
    self.manage_workers()
  File "/var/www/vhosts/edefrutos2025.xyz/httpdocs/.venv/lib/python3.8/site-packages/gunicorn/arbiter.py", line 570, in manage_workers
    self.spawn_workers()
  File "/var/www/vhosts/edefrutos2025.xyz/httpdocs/.venv/lib/python3.8/site-packages/gunicorn/arbiter.py", line 641, in spawn_workers
    self.spawn_worker()
  File "/var/www/vhosts/edefrutos2025.xyz/httpdocs/.venv/lib/python3.8/site-packages/gunicorn/arbiter.py", line 592, in spawn_worker
    pid = os.fork()
BlockingIOError: [Errno 11] Resource temporarily unavailable
Traceback (most recent call last):
  File "/var/www/vhosts/edefrutos2025.xyz/httpdocs/.venv/lib/python3.8/site-packages/gunicorn/arbiter.py", line 201, in run
    self.manage_workers()
  File "/var/www/vhosts/edefrutos2025.xyz/httpdocs/.venv/lib/python3.8/site-packages/gunicorn/arbiter.py", line 570, in manage_workers
    self.spawn_workers()
  File "/var/www/vhosts/edefrutos2025.xyz/httpdocs/.venv/lib/python3.8/site-packages/gunicorn/arbiter.py", line 641, in spawn_workers
    self.spawn_worker()
  File "/var/www/vhosts/edefrutos2025.xyz/httpdocs/.venv/lib/python3.8/site-packages/gunicorn/arbiter.py", line 592, in spawn_worker
    pid = os.fork()
BlockingIOError: [Errno 11] Resource temporarily unavailable
Traceback (most recent call last):
  File "/var/www/vhosts/edefrutos2025.xyz/httpdocs/.venv/lib/python3.8/site-packages/gunicorn/arbiter.py", line 608, in spawn_worker
  File "/var/www/vhosts/edefrutos2025.xyz/httpdocs/.venv/lib/python3.8/site-packages/gunicorn/workers/base.py", line 135, in init_process
  File "/var/www/vhosts/edefrutos2025.xyz/httpdocs/.venv/lib/python3.8/site-packages/gunicorn/workers/base.py", line 147, in load_wsgi
  File "/var/www/vhosts/edefrutos2025.xyz/httpdocs/.venv/lib/python3.8/site-packages/gunicorn/app/base.py", line 66, in wsgi
  File "/var/www/vhosts/edefrutos2025.xyz/httpdocs/.venv/lib/python3.8/site-packages/gunicorn/app/wsgiapp.py", line 57, in load
  File "/var/www/vhosts/edefrutos2025.xyz/httpdocs/.venv/lib/python3.8/site-packages/gunicorn/app/wsgiapp.py", line 47, in load_wsgiapp
  File "/var/www/vhosts/edefrutos2025.xyz/httpdocs/.venv/lib/python3.8/site-packages/gunicorn/util.py", line 370, in import_app
  File "/usr/lib/python3.8/importlib/__init__.py", line 127, in import_module
    return _bootstrap._gcd_import(name[level:], package, level)
  File "<frozen importlib._bootstrap>", line 1014, in _gcd_import
  File "<frozen importlib._bootstrap>", line 991, in _find_and_load
  File "<frozen importlib._bootstrap>", line 973, in _find_and_load_unlocked
ModuleNotFoundError: No module named 'wsgi'
Traceback (most recent call last):
  File "/var/www/vhosts/edefrutos2025.xyz/httpdocs/.venv/lib/python3.8/site-packages/gunicorn/arbiter.py", line 608, in spawn_worker
  File "/var/www/vhosts/edefrutos2025.xyz/httpdocs/.venv/lib/python3.8/site-packages/gunicorn/workers/base.py", line 135, in init_process
  File "/var/www/vhosts/edefrutos2025.xyz/httpdocs/.venv/lib/python3.8/site-packages/gunicorn/workers/base.py", line 147, in load_wsgi
  File "/var/www/vhosts/edefrutos2025.xyz/httpdocs/.venv/lib/python3.8/site-packages/gunicorn/app/base.py", line 66, in wsgi
  File "/var/www/vhosts/edefrutos2025.xyz/httpdocs/.venv/lib/python3.8/site-packages/gunicorn/app/wsgiapp.py", line 57, in load
  File "/var/www/vhosts/edefrutos2025.xyz/httpdocs/.venv/lib/python3.8/site-packages/gunicorn/app/wsgiapp.py", line 47, in load_wsgiapp
  File "/var/www/vhosts/edefrutos2025.xyz/httpdocs/.venv/lib/python3.8/site-packages/gunicorn/util.py", line 370, in import_app
  File "/usr/lib/python3.8/importlib/__init__.py", line 127, in import_module
    return _bootstrap._gcd_import(name[level:], package, level)
  File "<frozen importlib._bootstrap>", line 1014, in _gcd_import
  File "<frozen importlib._bootstrap>", line 991, in _find_and_load
  File "<frozen importlib._bootstrap>", line 973, in _find_and_load_unlocked
ModuleNotFoundError: No module named 'wsgi'
Traceback (most recent call last):
  File "/var/www/vhosts/edefrutos2025.xyz/httpdocs/.venv/lib/python3.8/site-packages/gunicorn/arbiter.py", line 608, in spawn_worker
  File "/var/www/vhosts/edefrutos2025.xyz/httpdocs/.venv/lib/python3.8/site-packages/gunicorn/workers/base.py", line 135, in init_process
  File "/var/www/vhosts/edefrutos2025.xyz/httpdocs/.venv/lib/python3.8/site-packages/gunicorn/workers/base.py", line 147, in load_wsgi
  File "/var/www/vhosts/edefrutos2025.xyz/httpdocs/.venv/lib/python3.8/site-packages/gunicorn/app/base.py", line 66, in wsgi
  File "/var/www/vhosts/edefrutos2025.xyz/httpdocs/.venv/lib/python3.8/site-packages/gunicorn/app/wsgiapp.py", line 57, in load
  File "/var/www/vhosts/edefrutos2025.xyz/httpdocs/.venv/lib/python3.8/site-packages/gunicorn/app/wsgiapp.py", line 47, in load_wsgiapp
  File "/var/www/vhosts/edefrutos2025.xyz/httpdocs/.venv/lib/python3.8/site-packages/gunicorn/util.py", line 370, in import_app
  File "/usr/lib/python3.8/importlib/__init__.py", line 127, in import_module
    return _bootstrap._gcd_import(name[level:], package, level)
  File "<frozen importlib._bootstrap>", line 1014, in _gcd_import
  File "<frozen importlib._bootstrap>", line 991, in _find_and_load
  File "<frozen importlib._bootstrap>", line 973, in _find_and_load_unlocked
ModuleNotFoundError: No module named 'wsgi'
Traceback (most recent call last):
  File "/var/www/vhosts/edefrutos2025.xyz/httpdocs/.venv/lib/python3.8/site-packages/gunicorn/arbiter.py", line 608, in spawn_worker
  File "/var/www/vhosts/edefrutos2025.xyz/httpdocs/.venv/lib/python3.8/site-packages/gunicorn/workers/base.py", line 135, in init_process
  File "/var/www/vhosts/edefrutos2025.xyz/httpdocs/.venv/lib/python3.8/site-packages/gunicorn/workers/base.py", line 147, in load_wsgi
  File "/var/www/vhosts/edefrutos2025.xyz/httpdocs/.venv/lib/python3.8/site-packages/gunicorn/app/base.py", line 66, in wsgi
  File "/var/www/vhosts/edefrutos2025.xyz/httpdocs/.venv/lib/python3.8/site-packages/gunicorn/app/wsgiapp.py", line 57, in load
  File "/var/www/vhosts/edefrutos2025.xyz/httpdocs/.venv/lib/python3.8/site-packages/gunicorn/app/wsgiapp.py", line 47, in load_wsgiapp
  File "/var/www/vhosts/edefrutos2025.xyz/httpdocs/.venv/lib/python3.8/site-packages/gunicorn/util.py", line 370, in import_app
  File "/usr/lib/python3.8/importlib/__init__.py", line 127, in import_module
    return _bootstrap._gcd_import(name[level:], package, level)
  File "<frozen importlib._bootstrap>", line 1014, in _gcd_import
  File "<frozen importlib._bootstrap>", line 991, in _find_and_load
  File "<frozen importlib._bootstrap>", line 973, in _find_and_load_unlocked
ModuleNotFoundError: No module named 'wsgi'
Traceback (most recent call last):
  File "/var/www/vhosts/edefrutos2025.xyz/httpdocs/.venv/lib/python3.8/site-packages/gunicorn/arbiter.py", line 608, in spawn_worker
  File "/var/www/vhosts/edefrutos2025.xyz/httpdocs/.venv/lib/python3.8/site-packages/gunicorn/workers/base.py", line 135, in init_process
  File "/var/www/vhosts/edefrutos2025.xyz/httpdocs/.venv/lib/python3.8/site-packages/gunicorn/workers/base.py", line 147, in load_wsgi
  File "/var/www/vhosts/edefrutos2025.xyz/httpdocs/.venv/lib/python3.8/site-packages/gunicorn/app/base.py", line 66, in wsgi
  File "/var/www/vhosts/edefrutos2025.xyz/httpdocs/.venv/lib/python3.8/site-packages/gunicorn/app/wsgiapp.py", line 57, in load
  File "/var/www/vhosts/edefrutos2025.xyz/httpdocs/.venv/lib/python3.8/site-packages/gunicorn/app/wsgiapp.py", line 47, in load_wsgiapp
  File "/var/www/vhosts/edefrutos2025.xyz/httpdocs/.venv/lib/python3.8/site-packages/gunicorn/util.py", line 370, in import_app
  File "/usr/lib/python3.8/importlib/__init__.py", line 127, in import_module
    return _bootstrap._gcd_import(name[level:], package, level)
  File "<frozen importlib._bootstrap>", line 1014, in _gcd_import
  File "<frozen importlib._bootstrap>", line 991, in _find_and_load
  File "<frozen importlib._bootstrap>", line 973, in _find_and_load_unlocked
ModuleNotFoundError: No module named 'wsgi'
Traceback (most recent call last):
  File "/var/www/vhosts/edefrutos2025.xyz/httpdocs/.venv/lib/python3.8/site-packages/gunicorn/arbiter.py", line 608, in spawn_worker
  File "/var/www/vhosts/edefrutos2025.xyz/httpdocs/.venv/lib/python3.8/site-packages/gunicorn/workers/base.py", line 135, in init_process
  File "/var/www/vhosts/edefrutos2025.xyz/httpdocs/.venv/lib/python3.8/site-packages/gunicorn/workers/base.py", line 147, in load_wsgi
  File "/var/www/vhosts/edefrutos2025.xyz/httpdocs/.venv/lib/python3.8/site-packages/gunicorn/app/base.py", line 66, in wsgi
  File "/var/www/vhosts/edefrutos2025.xyz/httpdocs/.venv/lib/python3.8/site-packages/gunicorn/app/wsgiapp.py", line 57, in load
  File "/var/www/vhosts/edefrutos2025.xyz/httpdocs/.venv/lib/python3.8/site-packages/gunicorn/app/wsgiapp.py", line 47, in load_wsgiapp
  File "/var/www/vhosts/edefrutos2025.xyz/httpdocs/.venv/lib/python3.8/site-packages/gunicorn/util.py", line 370, in import_app
  File "/usr/lib/python3.8/importlib/__init__.py", line 127, in import_module
    return _bootstrap._gcd_import(name[level:], package, level)
  File "<frozen importlib._bootstrap>", line 1014, in _gcd_import
  File "<frozen importlib._bootstrap>", line 991, in _find_and_load
  File "<frozen importlib._bootstrap>", line 973, in _find_and_load_unlocked
ModuleNotFoundError: No module named 'wsgi'
Traceback (most recent call last):
  File "/var/www/vhosts/edefrutos2025.xyz/httpdocs/.venv/lib/python3.8/site-packages/gunicorn/arbiter.py", line 201, in run
    self.manage_workers()
  File "/var/www/vhosts/edefrutos2025.xyz/httpdocs/.venv/lib/python3.8/site-packages/gunicorn/arbiter.py", line 570, in manage_workers
    self.spawn_workers()
  File "/var/www/vhosts/edefrutos2025.xyz/httpdocs/.venv/lib/python3.8/site-packages/gunicorn/arbiter.py", line 641, in spawn_workers
    self.spawn_worker()
  File "/var/www/vhosts/edefrutos2025.xyz/httpdocs/.venv/lib/python3.8/site-packages/gunicorn/arbiter.py", line 592, in spawn_worker
    pid = os.fork()
BlockingIOError: [Errno 11] Resource temporarily unavailable
Traceback (most recent call last):
  File "/var/www/vhosts/edefrutos2025.xyz/httpdocs/.venv/lib/python3.8/site-packages/gunicorn/arbiter.py", line 201, in run
    self.manage_workers()
  File "/var/www/vhosts/edefrutos2025.xyz/httpdocs/.venv/lib/python3.8/site-packages/gunicorn/arbiter.py", line 570, in manage_workers
    self.spawn_workers()
  File "/var/www/vhosts/edefrutos2025.xyz/httpdocs/.venv/lib/python3.8/site-packages/gunicorn/arbiter.py", line 641, in spawn_workers
    self.spawn_worker()
  File "/var/www/vhosts/edefrutos2025.xyz/httpdocs/.venv/lib/python3.8/site-packages/gunicorn/arbiter.py", line 592, in spawn_worker
    pid = os.fork()
BlockingIOError: [Errno 11] Resource temporarily unavailable
Traceback (most recent call last):
  File "/var/www/vhosts/edefrutos2025.xyz/httpdocs/.venv/lib/python3.8/site-packages/gunicorn/arbiter.py", line 201, in run
    self.manage_workers()
  File "/var/www/vhosts/edefrutos2025.xyz/httpdocs/.venv/lib/python3.8/site-packages/gunicorn/arbiter.py", line 570, in manage_workers
    self.spawn_workers()
  File "/var/www/vhosts/edefrutos2025.xyz/httpdocs/.venv/lib/python3.8/site-packages/gunicorn/arbiter.py", line 641, in spawn_workers
    self.spawn_worker()
  File "/var/www/vhosts/edefrutos2025.xyz/httpdocs/.venv/lib/python3.8/site-packages/gunicorn/arbiter.py", line 592, in spawn_worker
    pid = os.fork()
BlockingIOError: [Errno 11] Resource temporarily unavailable
